<?xml version="1.0" ?>
<!-- =================================================================================== -->
<!-- |    This document was autogenerated by xacro from /home/marcos/mrm_ws/src/modelo_description/urdf/modelo.xacro | -->
<!-- |    EDITING THIS FILE BY HAND IS NOT RECOMMENDED                                 | -->
<!-- =================================================================================== -->
<!-- rosrun gazebo_ros spawn_model -file /home/marcos/mrm_ws/src/modelo_description/urdf/modelo_gazebo.urdf> -urdf -x 0 -y 0 -z 1 -model modelo -->
<!-- =================================================================================== -->

<robot name="modelo">
    <material name="silver">
        <color rgba="0.700 0.700 0.700 1.000" />
    </material>
    <material name="black">
        <color rgba="0.0 0.0 0.0 1.0" />
    </material>
    <material name="blue">
        <color rgba="0.0 0.0 0.8 1.0" />
    </material>
    <material name="green">
        <color rgba="0.0 0.8 0.0 1.0" />
    </material>
    <material name="grey">
        <color rgba="0.2 0.2 0.2 1.0" />
    </material>
    <material name="orange">
        <color rgba="1.0 0.4235294117647059 0.0392156862745098 1.0" />
    </material>
    <material name="brown">
        <color rgba="0.8705882352941177 0.8117647058823529 0.7647058823529411 1.0" />
    </material>
    <material name="red">
        <color rgba="0.8 0.0 0.0 1.0" />
    </material>
    <material name="white">
        <color rgba="1.0 1.0 1.0 1.0" />
    </material>
    <transmission name="rev2_tran">
        <type>transmission_interface/SimpleTransmission</type>
        <joint name="rev2">
            <hardwareInterface>hardware_interface/EffortJointInterface</hardwareInterface>
        </joint>
        <actuator name="rev2_actr">
            <hardwareInterface>hardware_interface/EffortJointInterface</hardwareInterface>
            <mechanicalReduction>1</mechanicalReduction>
        </actuator>
    </transmission>
    <transmission name="rev3_tran">
        <type>transmission_interface/SimpleTransmission</type>
        <joint name="rev3">
            <hardwareInterface>hardware_interface/EffortJointInterface</hardwareInterface>
        </joint>
        <actuator name="rev3_actr">
            <hardwareInterface>hardware_interface/EffortJointInterface</hardwareInterface>
            <mechanicalReduction>1</mechanicalReduction>
        </actuator>
    </transmission>
    <transmission name="rev4_tran">
        <type>transmission_interface/SimpleTransmission</type>
        <joint name="rev4">
            <hardwareInterface>hardware_interface/EffortJointInterface</hardwareInterface>
        </joint>
        <actuator name="rev4_actr">
            <hardwareInterface>hardware_interface/EffortJointInterface</hardwareInterface>
            <mechanicalReduction>1</mechanicalReduction>
        </actuator>
    </transmission>
    <transmission name="rev5_tran">
        <type>transmission_interface/SimpleTransmission</type>
        <joint name="rev5">
            <hardwareInterface>hardware_interface/EffortJointInterface</hardwareInterface>
        </joint>
        <actuator name="rev5_actr">
            <hardwareInterface>hardware_interface/EffortJointInterface</hardwareInterface>
            <mechanicalReduction>1</mechanicalReduction>
        </actuator>
    </transmission>
    <transmission name="rev6_tran">
        <type>transmission_interface/SimpleTransmission</type>
        <joint name="rev6">
            <hardwareInterface>hardware_interface/EffortJointInterface</hardwareInterface>
        </joint>
        <actuator name="rev6_actr">
            <hardwareInterface>hardware_interface/EffortJointInterface</hardwareInterface>
            <mechanicalReduction>1</mechanicalReduction>
        </actuator>
    </transmission>
    <transmission name="rev7_tran">
        <type>transmission_interface/SimpleTransmission</type>
        <joint name="rev7">
            <hardwareInterface>hardware_interface/EffortJointInterface</hardwareInterface>
        </joint>
        <actuator name="rev7_actr">
            <hardwareInterface>hardware_interface/EffortJointInterface</hardwareInterface>
            <mechanicalReduction>1</mechanicalReduction>
        </actuator>
    </transmission>
    <gazebo>
        <plugin filename="libgazebo_ros_control.so" name="control" />
    </gazebo>
    <gazebo reference="base_link">
        <material>Gazebo/Silver</material>
        <mu1>0.2</mu1>
        <mu2>0.2</mu2>
        <selfCollide>true</selfCollide>
        <dynamics damping="1" friction="1" />
        <gravity>true</gravity>
    </gazebo>
    <gazebo reference="link_1">
        <material>Gazebo/Silver</material>
        <mu1>0.2</mu1>
        <mu2>0.2</mu2>
        <selfCollide>true</selfCollide>
        <dynamics damping="1" friction="1" />
    </gazebo>
    <gazebo reference="link_2">
        <material>Gazebo/Silver</material>
        <mu1>0.2</mu1>
        <mu2>0.2</mu2>
        <selfCollide>true</selfCollide>
        <dynamics damping="1" friction="1" />
    </gazebo>
    <gazebo reference="link_3">
        <material>Gazebo/Silver</material>
        <mu1>0.2</mu1>
        <mu2>0.2</mu2>
        <selfCollide>true</selfCollide>
        <dynamics damping="1" friction="1" />
    </gazebo>
    <gazebo reference="link_4">
        <material>Gazebo/Silver</material>
        <mu1>0.2</mu1>
        <mu2>0.2</mu2>
        <selfCollide>true</selfCollide>
        <dynamics damping="1" friction="1" />
    </gazebo>
    <gazebo reference="link_5">
        <material>Gazebo/Silver</material>
        <mu1>0.2</mu1>
        <mu2>0.2</mu2>
        <selfCollide>true</selfCollide>
        <dynamics damping="1" friction="1" />
    </gazebo>
    <gazebo reference="link_6">
        <material>Gazebo/Silver</material>
        <mu1>0.2</mu1>
        <mu2>0.2</mu2>
        <selfCollide>true</selfCollide>
        <dynamics damping="1" friction="1" />
    </gazebo>
    <gazebo reference="link_7">
        <material>Gazebo/Silver</material>
        <mu1>0.2</mu1>
        <mu2>0.2</mu2>
        <selfCollide>true</selfCollide>
        <dynamics damping="1" friction="1" />
    </gazebo>
    <gazebo reference="NEMA17_1">
        <material>Gazebo/Silver</material>
        <mu1>0.2</mu1>
        <mu2>0.2</mu2>
        <selfCollide>true</selfCollide>
        <dynamics damping="1" friction="1" />
    </gazebo>
    <gazebo reference="NEMA17_2">
        <material>Gazebo/Silver</material>
        <mu1>0.2</mu1>
        <mu2>0.2</mu2>
        <selfCollide>true</selfCollide>
        <dynamics damping="1" friction="1" />
    </gazebo>
    <gazebo reference="NEMA23_1">
        <material>Gazebo/Silver</material>
        <mu1>0.2</mu1>
        <mu2>0.2</mu2>
        <selfCollide>true</selfCollide>
        <dynamics damping="1" friction="1" />
    </gazebo>
    <gazebo reference="NEMA23_2">
        <material>Gazebo/Silver</material>
        <mu1>0.2</mu1>
        <mu2>0.2</mu2>
        <selfCollide>true</selfCollide>
        <dynamics damping="1" friction="1" />
    </gazebo>
    <gazebo reference="garra">
        <material>Gazebo/Silver</material>
        <mu1>0.2</mu1>
        <mu2>0.2</mu2>
        <selfCollide>true</selfCollide>
        <dynamics damping="1" friction="1" />
    </gazebo>
    <!-- base Link -->
    <gazebo reference="base_link">
        <material>Gazebo/Orange</material>
    </gazebo>
    <!-- Link1 -->
    <gazebo reference="link_1">
        <material>Gazebo/Black</material>
    </gazebo>
    <!-- Link2 -->
    <gazebo reference="link_2">
        <material>Gazebo/Orange</material>
    </gazebo>
    <!-- Link3 -->
    <gazebo reference="link_3">
        <material>Gazebo/Black</material>
    </gazebo>
    <!-- Link4 -->
    <gazebo reference="link_4">
        <material>Gazebo/Orange</material>
    </gazebo>
    <!-- Link5 -->
    <gazebo reference="link_5">
        <material>Gazebo/Black</material>
    </gazebo>
    <!-- Link6 -->
    <gazebo reference="link_6">
        <material>Gazebo/Orange</material>
    </gazebo>
    <!-- Link7 -->
    <gazebo reference="link_7">
        <material>Gazebo/Black</material>
    </gazebo>
    <!-- garra -->
    <gazebo reference="garra">
        <material>Gazebo/Orange</material>
    </gazebo>
    <!-- NEMA17 1 -->
    <gazebo reference="NEMA17_1">
        <material>Gazebo/Red</material>
    </gazebo>
    <!-- NEMA17 2 -->
    <gazebo reference="NEMA17_2">
        <material>Gazebo/Red</material>
    </gazebo>
    <!-- NEMA23 1 -->
    <gazebo reference="NEMA23_1">
        <material>Gazebo/Red</material>
    </gazebo>
    <!-- NEMA23 2 -->
    <gazebo reference="NEMA23_2">
        <material>Gazebo/Red</material>
    </gazebo>
    <link name="base_link">
        
    <inertial>
                <origin rpy="0 0 0" xyz="1.3695408551062038e-15 0.0 0.02497017641605957" />
                <mass value="2.111798" />
                <inertia ixx="0.007474" ixy="0" ixz="0" iyy="0.007474" iyz="0" izz="0.01407" />
            </inertial>

            <visual>
                <origin rpy="0 0 0" xyz="0 0 0" />
                <geometry>
                    <mesh filename="package://modelo_description/meshes/base_link.stl" scale="0.001 0.001 0.001" />
                </geometry>
                <material name="orange" />
            </visual>
            <collision>
                <origin rpy="0 0 0" xyz="0 0 0" />
                <geometry>
                    <mesh filename="package://modelo_description/meshes/base_link.stl" scale="0.001 0.001 0.001" />
                </geometry>
            </collision>
        </link>
        <link name="link_1">
            
    <inertial>
                <origin rpy="0 0 0" xyz="-5.047483736354417e-10 -0.004392610218652343 0.04871320580870557" />
                <mass value="1.102554" />
                <inertia ixx="0.002237" ixy="0" ixz="0" iyy="0.002034" iyz="0.00005466295" izz="0.001997" />
            </inertial>

            <visual>
                <origin rpy="0 0 0" xyz="-0.0 -0.0 -0.05" />
                <geometry>
                    <mesh filename="package://modelo_description/meshes/link_1.stl" scale="0.001 0.001 0.001" />
                </geometry>
                <material name="blue" />
            </visual>
            <collision>
                <origin rpy="0 0 0" xyz="-0.0 -0.0 -0.05" />
                <geometry>
                    <mesh filename="package://modelo_description/meshes/link_1.stl" scale="0.001 0.001 0.001" />
                </geometry>
            </collision>
        </link>
        <link name="link_2">
            
    <inertial>
                <origin rpy="0 0 0" xyz="-7.11936857127372e-09 0.032249951644533474 0.02724437131426541" />
                <mass value="0.187945" />
                <inertia ixx="0.0005193" ixy="0" ixz="0" iyy="0.0002309" iyz="0" izz="0.0004174" />
            </inertial>

            <visual>
                <origin rpy="0 0 0" xyz="-0.0 -0.0 -0.157" />
                <geometry>
                    <mesh filename="package://modelo_description/meshes/link_2.stl" scale="0.001 0.001 0.001" />
                </geometry>
                <material name="orange" />
            </visual>
            <collision>
                <origin rpy="0 0 0" xyz="-0.0 -0.0 -0.157" />
                <geometry>
                    <mesh filename="package://modelo_description/meshes/link_2.stl" scale="0.001 0.001 0.001" />
                </geometry>
            </collision>
        </link>
        <link name="link_3">
            
    <inertial>
                <origin rpy="0 0 0" xyz="0.01009125669144174 7.91033905045424e-16 0.0825602906581889" />
                <origin rpy="0 0 0" xyz="0.01009125669144174 7.91033905045424e-16 0.0825602906581889" />
                <mass value="0.187945" />
                <inertia ixx="0.0005193" ixy="0" ixz="0" iyy="0.0002309" iyz="0" izz="0.0004174" />
            </inertial>

            <visual>
                <origin rpy="0 0 0" xyz="-0.005 -0.07 -0.22" />
                <geometry>
                    <mesh filename="package://modelo_description/meshes/link_3.stl" scale="0.001 0.001 0.001" />
                </geometry>
                <material name="blue" />
            </visual>
            <collision>
                <origin rpy="0 0 0" xyz="-0.005 -0.07 -0.22" />
                <geometry>
                    <mesh filename="package://modelo_description/meshes/link_3.stl" scale="0.001 0.001 0.001" />
                </geometry>
            </collision>
        </link>
        <link name="link_4">
            
    <inertial>
                <origin rpy="0 0 0" xyz="-0.04671583823132678 -0.006114743040103704 0.01335347313130314" />
                <mass value="0.126071" />
                <inertia ixx="0.000088940685" ixy="0" ixz="0.00000611033" iyy="0.0001763" iyz="0" izz="0.0001979" />
            </inertial>

            <visual>
                <origin rpy="0 0 0" xyz="-0.005 -0.07 -0.42" />
                <geometry>
                    <mesh filename="package://modelo_description/meshes/link_4.stl" scale="0.001 0.001 0.001" />
                </geometry>
                <material name="orange" />
            </visual>
            <collision>
                <origin rpy="0 0 0" xyz="-0.005 -0.07 -0.42" />
                <geometry>
                    <mesh filename="package://modelo_description/meshes/link_4.stl" scale="0.001 0.001 0.001" />
                </geometry>
            </collision>
        </link>
        <link name="link_5">
            
    <inertial>
                <origin rpy="0 0 0" xyz="-0.00044650849455328545 -0.05778279171036697 -2.7755575615628914e-16" />
                <mass value="0.488452" />
                <inertia ixx="0.001155" ixy="0" ixz="0" iyy="0.0007053" iyz="0" izz="0.001054" />
            </inertial>

            <visual>
                <origin rpy="0 0 0" xyz="0.075 -0.035 -0.42" />
                <geometry>
                    <mesh filename="package://modelo_description/meshes/link_5.stl" scale="0.001 0.001 0.001" />
                </geometry>
                <material name="blue" />
            </visual>
            <collision>
                <origin rpy="0 0 0" xyz="0.075 -0.035 -0.42" />
                <geometry>
                    <mesh filename="package://modelo_description/meshes/link_5.stl" scale="0.001 0.001 0.001" />
                </geometry>
            </collision>
        </link>
        <link name="link_6">
            
    <inertial>
                <origin rpy="0 0 0" xyz="-0.00683271348055893 -8.116383311621012e-06 0.024999999998279177" />
                <mass value="0.0123861" />
                <inertia ixx="0.000039194942" ixy="0" ixz="0" iyy="0.000058851989" iyz="0" izz="0.000056762072" />
            </inertial>

            <visual>
                <origin rpy="0 0 0" xyz="0.07679 0.070058 -0.395" />
                <geometry>
                    <mesh filename="package://modelo_description/meshes/link_6.stl" scale="0.001 0.001 0.001" />
                </geometry>
                <material name="orange" />
            </visual>
            <collision>
                <origin rpy="0 0 0" xyz="0.07679 0.070058 -0.395" />
                <geometry>
                    <mesh filename="package://modelo_description/meshes/link_6.stl" scale="0.001 0.001 0.001" />
                </geometry>
            </collision>
        </link>
        <link name="link_7">
            
    <inertial>
                <origin rpy="0 0 0" xyz="-0.008082563695983674 -9.665388285423626e-06 -3.3306690738754696e-16" />
                <mass value="0.001457" />
                <inertia ixx="0.000003254171" ixy="0" ixz="0" iyy="0.000001820288" iyz="0" izz="0.000001820286" />
            </inertial>

            <visual>
                <origin rpy="0 0 0" xyz="0.11679 0.070105 -0.42" />
                <geometry>
                    <mesh filename="package://modelo_description/meshes/link_7.stl" scale="0.001 0.001 0.001" />
                </geometry>
                <material name="blue" />
            </visual>
            <collision>
                <origin rpy="0 0 0" xyz="0.11679 0.070105 -0.42" />
                <geometry>
                    <mesh filename="package://modelo_description/meshes/link_7.stl" scale="0.001 0.001 0.001" />
                </geometry>
            </collision>
        </link>
        <link name="NEMA17_1">
            
    <inertial>
                <origin rpy="0 0 0" xyz="-0.017979645478686204 9.8483682348105e-08 -7.507921800931072e-08" />
                <mass value="0.37807" />
                <inertia ixx="0.000088375151" ixy="0" ixz="0" iyy="0.000080538853" iyz="0" izz="0.000080539183" />
            </inertial>

            <visual>
                <origin rpy="0 0 0" xyz="0.005 -0.07 -0.42" />
                <geometry>
                    <mesh filename="package://modelo_description/meshes/NEMA17_1.stl" scale="0.001 0.001 0.001" />
                </geometry>
                <material name="orange" />
            </visual>
            <collision>
                <origin rpy="0 0 0" xyz="0.005 -0.07 -0.42" />
                <geometry>
                    <mesh filename="package://modelo_description/meshes/NEMA17_1.stl" scale="0.001 0.001 0.001" />
                </geometry>
            </collision>
        </link>
        <link name="NEMA17_2">
            
    <inertial>
                <origin rpy="0 0 0" xyz="4.619561776164627e-08 0.01797957811301021 -3.299982803683932e-08" />
                <mass value="0.37807" />
                <inertia ixx="0.000088375151" ixy="0" ixz="0" iyy="0.000080538853" iyz="0" izz="0.000080539183" />
            </inertial>

            <visual>
                <origin rpy="0 0 0" xyz="0.075 -0.045 -0.42" />
                <geometry>
                    <mesh filename="package://modelo_description/meshes/NEMA17_2.stl" scale="0.001 0.001 0.001" />
                </geometry>
                <material name="blue" />
            </visual>
            <collision>
                <origin rpy="0 0 0" xyz="0.075 -0.045 -0.42" />
                <geometry>
                    <mesh filename="package://modelo_description/meshes/NEMA17_2.stl" scale="0.001 0.001 0.001" />
                </geometry>
            </collision>
        </link>
        <link name="NEMA23_1">
            
    <inertial>
                <origin rpy="0 0 0" xyz="2.216087647950953e-08 -2.5678396917215573e-05 0.03903179757969141" />
                <mass value="1.71147" />
                <inertia ixx="0.00124" ixy="0" ixz="0" iyy="0.001239" iyz="0.000001398796" izz="0.0007837" />
            </inertial>

            <visual>
                <origin rpy="0 0 0" xyz="-0.0 0.008236 -0.17" />
                <geometry>
                    <mesh filename="package://modelo_description/meshes/NEMA23_1.stl" scale="0.001 0.001 0.001" />
                </geometry>
                <material name="orange" />
            </visual>
            <collision>
                <origin rpy="0 0 0" xyz="-0.0 0.008236 -0.17" />
                <geometry>
                    <mesh filename="package://modelo_description/meshes/NEMA23_1.stl" scale="0.001 0.001 0.001" />
                </geometry>
            </collision>
        </link>
        <link name="NEMA23_2">
            
    <inertial>
                <origin rpy="0 0 0" xyz="-0.03903179757969144 -2.5678396917222512e-05 2.2160876439469845e-08" />
                <mass value="1.71147" />
                <inertia ixx="0.00124" ixy="0" ixz="0" iyy="0.001239" iyz="0.000001398796" izz="0.0007837" />
            </inertial>

            <visual>
                <origin rpy="0 0 0" xyz="0.005 -0.07 -0.22" />
                <geometry>
                    <mesh filename="package://modelo_description/meshes/NEMA23_2.stl" scale="0.001 0.001 0.001" />
                </geometry>
                <material name="blue" />
            </visual>
            <collision>
                <origin rpy="0 0 0" xyz="0.005 -0.07 -0.22" />
                <geometry>
                    <mesh filename="package://modelo_description/meshes/NEMA23_2.stl" scale="0.001 0.001 0.001" />
                </geometry>
            </collision>
        </link>
        <link name="garra">
            
    <inertial>
            <origin rpy="0 0 0" xyz="-0.03590834296259646 -3.6387512495197893e-05 -0.00275221699917072" />
            <mass value="0.0195293" />
            <inertia ixx="0.0001552" ixy="0" ixz="0" iyy="0.0001843" iyz="0" izz="0.0001331" />
        </inertial>

        <visual>
            <origin rpy="0 0 0" xyz="0.13179 0.070123 -0.42" />
            <geometry>
                <mesh filename="package://modelo_description/meshes/garra.stl" scale="0.001 0.001 0.001" />
            </geometry>
            <material name="orange" />
        </visual>
        <collision>
            <origin rpy="0 0 0" xyz="0.13179 0.070123 -0.42" />
            <geometry>
                <mesh filename="package://modelo_description/meshes/garra.stl" scale="0.001 0.001 0.001" />
            </geometry>
        </collision>
    </link>
    <link name="world" />
    <joint name="fixed" type="fixed">
        <parent link="world" />
        <child link="base_link" />
    </joint>
    <joint name="Rigid1" type="fixed">
        <origin rpy="0 0 0" xyz="0.0 0.0 0.05" />
        <parent link="base_link" />
        <child link="link_1" />
    </joint>
    <joint name="rev2" type="continuous">
        <origin rpy="0 0 0" xyz="0.0 0.0 0.107" />
        <parent link="link_1" />
        <child link="link_2" />
        <axis xyz="0 0 -1" />
    </joint>
    <joint name="rev3" type="revolute">
        <origin rpy="0 0 0" xyz="0.005 0.07 0.063" />
        <parent link="link_2" />
        <child link="link_3" />
        <axis xyz="-1 0 0" />
        <limit effort="100" lower="0.0" upper="1.570796" velocity="10" />
    </joint>
    <joint name="rev4" type="revolute">
        <origin rpy="0 0 0" xyz="0.0 0.0 0.2" />
        <parent link="link_3" />
        <child link="link_4" />
        <axis xyz="-1 0 0" />
        <limit effort="100" lower="0.0" upper="3.141593" velocity="10" />
    </joint>
    <joint name="rev5" type="continuous">
        <origin rpy="0 0 0" xyz="-0.08 -0.035 0.0" />
        <parent link="link_4" />
        <child link="link_5" />
        <axis xyz="0 1 0" />
    </joint>
    <joint name="rev6" type="revolute">
        <origin rpy="0 0 0" xyz="-0.00179 -0.105058 -0.025" />
        <parent link="link_5" />
        <child link="link_6" />
        <axis xyz="0 0 -1" />
        <limit effort="100" lower="-3.141593" upper="0.0" velocity="10" />
    </joint>
    <joint name="rev7" type="continuous">
        <origin rpy="0 0 0" xyz="-0.04 -4.7e-05 0.025" />
        <parent link="link_6" />
        <child link="link_7" />
        <axis xyz="1 0 0" />
    </joint>
    <joint name="Rigid8" type="fixed">
        <origin rpy="0 0 0" xyz="-0.01 0.0 0.0" />
        <parent link="link_4" />
        <child link="NEMA17_1" />
    </joint>
    <joint name="Rigid9" type="fixed">
        <origin rpy="0 0 0" xyz="-0.08 -0.025 0.0" />
        <parent link="link_4" />
        <child link="NEMA17_2" />
    </joint>
    <joint name="Rigid10" type="fixed">
        <origin rpy="0 0 0" xyz="0.0 -0.008236 0.013" />
        <parent link="link_2" />
        <child link="NEMA23_1" />
    </joint>
    <joint name="Rigid11" type="fixed">
        <origin rpy="0 0 0" xyz="-0.005 0.07 0.063" />
        <parent link="link_2" />
        <child link="NEMA23_2" />
    </joint>
    <joint name="Rigid12" type="fixed">
        <origin rpy="0 0 0" xyz="-0.015 -1.8e-05 0.0" />
        <parent link="link_7" />
        <child link="garra" />
    </joint>
    <gazebo>
        <plugin filename="libgazebo_ros_control.so" name="gazebo_ros_control">
            <robotNamespace>/modelo</robotNamespace>
        </plugin>
    </gazebo>
    <transmission name="trans_rev2">
        <type>transmission_interface/SimpleTransmission</type>
        <joint name="rev2">
            <hardwareInterface>hardware_interface/EffortJointInterface</hardwareInterface>
        </joint>
        <actuator name="rev2_motor">
            <hardwareInterface>hardware_interface/EffortJointInterface</hardwareInterface>
            <mechanicalReduction>1</mechanicalReduction>
        </actuator>
    </transmission>
    <transmission name="trans_rev3">
        <type>transmission_interface/SimpleTransmission</type>
        <joint name="rev3">
            <hardwareInterface>hardware_interface/EffortJointInterface</hardwareInterface>
        </joint>
        <actuator name="rev3_motor">
            <hardwareInterface>hardware_interface/EffortJointInterface</hardwareInterface>
            <mechanicalReduction>1</mechanicalReduction>
        </actuator>
    </transmission>
    <transmission name="trans_rev4">
        <type>transmission_interface/SimpleTransmission</type>
        <joint name="rev4">
            <hardwareInterface>hardware_interface/EffortJointInterface</hardwareInterface>
        </joint>
        <actuator name="rev4_motor">
            <hardwareInterface>hardware_interface/EffortJointInterface</hardwareInterface>
            <mechanicalReduction>1</mechanicalReduction>
        </actuator>
    </transmission>
    <transmission name="trans_rev5">
        <type>transmission_interface/SimpleTransmission</type>
        <joint name="rev5">
            <hardwareInterface>hardware_interface/EffortJointInterface</hardwareInterface>
        </joint>
        <actuator name="rev5_motor">
            <hardwareInterface>hardware_interface/EffortJointInterface</hardwareInterface>
            <mechanicalReduction>1</mechanicalReduction>
        </actuator>
    </transmission>
    <transmission name="trans_rev6">
        <type>transmission_interface/SimpleTransmission</type>
        <joint name="rev6">
            <hardwareInterface>hardware_interface/EffortJointInterface</hardwareInterface>
        </joint>
        <actuator name="rev6_motor">
            <hardwareInterface>hardware_interface/EffortJointInterface</hardwareInterface>
            <mechanicalReduction>1</mechanicalReduction>
        </actuator>
    </transmission>
    <transmission name="trans_rev7">
        <type>transmission_interface/SimpleTransmission</type>
        <joint name="rev7">
            <hardwareInterface>hardware_interface/EffortJointInterface</hardwareInterface>
        </joint>
        <actuator name="rev7_motor">
            <hardwareInterface>hardware_interface/EffortJointInterface</hardwareInterface>
            <mechanicalReduction>1</mechanicalReduction>
        </actuator>
    </transmission>
    <gazebo>
        <plugin name="gazebo_ros_control" filename="libgazebo_ros_control.so">
            <robotNamespace>/</robotNamespace>
        </plugin>
    </gazebo>
</robot>

<transmission name="rev2_tran">
        <type>transmission_interface/SimpleTransmission</type>
        <joint name="rev2">
            <hardwareInterface>hardware_interface/EffortJointInterface</hardwareInterface>
        </joint>
        <actuator name="rev2_actr">
            <hardwareInterface>hardware_interface/EffortJointInterface</hardwareInterface>
            <mechanicalReduction>1</mechanicalReduction>
        </actuator>
    </transmission>
    <transmission name="rev3_tran">
        <type>transmission_interface/SimpleTransmission</type>
        <joint name="rev3">
            <hardwareInterface>hardware_interface/EffortJointInterface</hardwareInterface>
        </joint>
        <actuator name="rev3_actr">
            <hardwareInterface>hardware_interface/EffortJointInterface</hardwareInterface>
            <mechanicalReduction>1</mechanicalReduction>
        </actuator>
    </transmission>
    <transmission name="rev4_tran">
        <type>transmission_interface/SimpleTransmission</type>
        <joint name="rev4">
            <hardwareInterface>hardware_interface/EffortJointInterface</hardwareInterface>
        </joint>
        <actuator name="rev4_actr">
            <hardwareInterface>hardware_interface/EffortJointInterface</hardwareInterface>
            <mechanicalReduction>1</mechanicalReduction>
        </actuator>
    </transmission>
    <transmission name="rev5_tran">
        <type>transmission_interface/SimpleTransmission</type>
        <joint name="rev5">
            <hardwareInterface>hardware_interface/EffortJointInterface</hardwareInterface>
        </joint>
        <actuator name="rev5_actr">
            <hardwareInterface>hardware_interface/EffortJointInterface</hardwareInterface>
            <mechanicalReduction>1</mechanicalReduction>
        </actuator>
    </transmission>
    <transmission name="rev6_tran">
        <type>transmission_interface/SimpleTransmission</type>
        <joint name="rev6">
            <hardwareInterface>hardware_interface/EffortJointInterface</hardwareInterface>
        </joint>
        <actuator name="rev6_actr">
            <hardwareInterface>hardware_interface/EffortJointInterface</hardwareInterface>
            <mechanicalReduction>1</mechanicalReduction>
        </actuator>
    </transmission>
    <transmission name="rev7_tran">
        <type>transmission_interface/SimpleTransmission</type>
        <joint name="rev7">
            <hardwareInterface>hardware_interface/EffortJointInterface</hardwareInterface>
        </joint>
        <actuator name="rev7_actr">
            <hardwareInterface>hardware_interface/EffortJointInterface</hardwareInterface>
            <mechanicalReduction>1</mechanicalReduction>
        </actuator>
    </transmission>
    <gazebo>
        <plugin filename="libgazebo_ros_control.so" name="control" />
    </gazebo>
    <gazebo reference="base_link">
        <material>Gazebo/Silver</material>
        <mu1>0.2</mu1>
        <mu2>0.2</mu2>
        <selfCollide>true</selfCollide>
        <dynamics damping="1" friction="1" />
        <gravity>true</gravity>
    </gazebo>
    <gazebo reference="link_1">
        <material>Gazebo/Silver</material>
        <mu1>0.2</mu1>
        <mu2>0.2</mu2>
        <selfCollide>true</selfCollide>
        <dynamics damping="1" friction="1" />
    </gazebo>
    <gazebo reference="link_2">
        <material>Gazebo/Silver</material>
        <mu1>0.2</mu1>
        <mu2>0.2</mu2>
        <selfCollide>true</selfCollide>
        <dynamics damping="1" friction="1" />
    </gazebo>
    <gazebo reference="link_3">
        <material>Gazebo/Silver</material>
        <mu1>0.2</mu1>
        <mu2>0.2</mu2>
        <selfCollide>true</selfCollide>
        <dynamics damping="1" friction="1" />
    </gazebo>
    <gazebo reference="link_4">
        <material>Gazebo/Silver</material>
        <mu1>0.2</mu1>
        <mu2>0.2</mu2>
        <selfCollide>true</selfCollide>
        <dynamics damping="1" friction="1" />
    </gazebo>
    <gazebo reference="link_5">
        <material>Gazebo/Silver</material>
        <mu1>0.2</mu1>
        <mu2>0.2</mu2>
        <selfCollide>true</selfCollide>
        <dynamics damping="1" friction="1" />
    </gazebo>
    <gazebo reference="link_6">
        <material>Gazebo/Silver</material>
        <mu1>0.2</mu1>
        <mu2>0.2</mu2>
        <selfCollide>true</selfCollide>
        <dynamics damping="1" friction="1" />
    </gazebo>
    <gazebo reference="link_7">
        <material>Gazebo/Silver</material>
        <mu1>0.2</mu1>
        <mu2>0.2</mu2>
        <selfCollide>true</selfCollide>
        <dynamics damping="1" friction="1" />
    </gazebo>
    <gazebo reference="NEMA17_1">
        <material>Gazebo/Silver</material>
        <mu1>0.2</mu1>
        <mu2>0.2</mu2>
        <selfCollide>true</selfCollide>
        <dynamics damping="1" friction="1" />
    </gazebo>
    <gazebo reference="NEMA17_2">
        <material>Gazebo/Silver</material>
        <mu1>0.2</mu1>
        <mu2>0.2</mu2>
        <selfCollide>true</selfCollide>
        <dynamics damping="1" friction="1" />
    </gazebo>
    <gazebo reference="NEMA23_1">
        <material>Gazebo/Silver</material>
        <mu1>0.2</mu1>
        <mu2>0.2</mu2>
        <selfCollide>true</selfCollide>
        <dynamics damping="1" friction="1" />
    </gazebo>
    <gazebo reference="NEMA23_2">
        <material>Gazebo/Silver</material>
        <mu1>0.2</mu1>
        <mu2>0.2</mu2>
        <selfCollide>true</selfCollide>
        <dynamics damping="1" friction="1" />
    </gazebo>
    <gazebo reference="garra">
        <material>Gazebo/Silver</material>
        <mu1>0.2</mu1>
        <mu2>0.2</mu2>
        <selfCollide>true</selfCollide>
        <dynamics damping="1" friction="1" />
    </gazebo>
    <!-- base Link -->
    <gazebo reference="base_link">
        <material>Gazebo/Orange</material>
    </gazebo>
    <!-- Link1 -->
    <gazebo reference="link_1">
        <material>Gazebo/Black</material>
    </gazebo>
    <!-- Link2 -->
    <gazebo reference="link_2">
        <material>Gazebo/Orange</material>
    </gazebo>
    <!-- Link3 -->
    <gazebo reference="link_3">
        <material>Gazebo/Black</material>
    </gazebo>
    <!-- Link4 -->
    <gazebo reference="link_4">
        <material>Gazebo/Orange</material>
    </gazebo>
    <!-- Link5 -->
    <gazebo reference="link_5">
        <material>Gazebo/Black</material>
    </gazebo>
    <!-- Link6 -->
    <gazebo reference="link_6">
        <material>Gazebo/Orange</material>
    </gazebo>
    <!-- Link7 -->
    <gazebo reference="link_7">
        <material>Gazebo/Black</material>
    </gazebo>
    <!-- garra -->
    <gazebo reference="garra">
        <material>Gazebo/Orange</material>
    </gazebo>
    <!-- NEMA17 1 -->
    <gazebo reference="NEMA17_1">
        <material>Gazebo/Red</material>
    </gazebo>
    <!-- NEMA17 2 -->
    <gazebo reference="NEMA17_2">
        <material>Gazebo/Red</material>
    </gazebo>
    <!-- NEMA23 1 -->
    <gazebo reference="NEMA23_1">
        <material>Gazebo/Red</material>
    </gazebo>
    <!-- NEMA23 2 -->
    <gazebo reference="NEMA23_2">
        <material>Gazebo/Red</material>
    </gazebo>
    <link name="base_link">
        <inertial>
            <origin rpy="0 0 0" xyz="1.3695408551062038e-15 0.0 0.02497017641605957" />
            <mass value="2.111798" />
            <inertia ixx="0.007474" ixy="0" ixz="0" iyy="0.007474" iyz="0" izz="0.01407" />
        </inertial>
        <visual>
            <origin rpy="0 0 0" xyz="0 0 0" />
            <geometry>
                <mesh filename="package://modelo_description/meshes/base_link.stl" scale="0.001 0.001 0.001" />
            </geometry>
            <material name="orange" />
        </visual>
        <collision>
            <origin rpy="0 0 0" xyz="0 0 0" />
            <geometry>
                <mesh filename="package://modelo_description/meshes/base_link.stl" scale="0.001 0.001 0.001" />
            </geometry>
        </collision>
    </link>
    <link name="link_1">
        <inertial>
            <origin rpy="0 0 0" xyz="-5.047483736354417e-10 -0.004392610218652343 0.04871320580870557" />
            <mass value="1.102554" />
            <inertia ixx="0.002237" ixy="0" ixz="0" iyy="0.002034" iyz="0.00005466295" izz="0.001997" />
        </inertial>
        <visual>
            <origin rpy="0 0 0" xyz="-0.0 -0.0 -0.05" />
            <geometry>
                <mesh filename="package://modelo_description/meshes/link_1.stl" scale="0.001 0.001 0.001" />
            </geometry>
            <material name="blue" />
        </visual>
        <collision>
            <origin rpy="0 0 0" xyz="-0.0 -0.0 -0.05" />
            <geometry>
                <mesh filename="package://modelo_description/meshes/link_1.stl" scale="0.001 0.001 0.001" />
            </geometry>
        </collision>
    </link>
    <link name="link_2">
        <inertial>
            <origin rpy="0 0 0" xyz="-7.11936857127372e-09 0.032249951644533474 0.02724437131426541" />
            <mass value="0.187945" />
            <inertia ixx="0.0005193" ixy="0" ixz="0" iyy="0.0002309" iyz="0" izz="0.0004174" />
        </inertial>
        <visual>
            <origin rpy="0 0 0" xyz="-0.0 -0.0 -0.157" />
            <geometry>
                <mesh filename="package://modelo_description/meshes/link_2.stl" scale="0.001 0.001 0.001" />
            </geometry>
            <material name="orange" />
        </visual>
        <collision>
            <origin rpy="0 0 0" xyz="-0.0 -0.0 -0.157" />
            <geometry>
                <mesh filename="package://modelo_description/meshes/link_2.stl" scale="0.001 0.001 0.001" />
            </geometry>
        </collision>
    </link>
    <link name="link_3">
        <inertial>
            <origin rpy="0 0 0" xyz="0.01009125669144174 7.91033905045424e-16 0.0825602906581889" />
            <origin rpy="0 0 0" xyz="0.01009125669144174 7.91033905045424e-16 0.0825602906581889" />
            <mass value="0.187945" />
            <inertia ixx="0.0005193" ixy="0" ixz="0" iyy="0.0002309" iyz="0" izz="0.0004174" />
        </inertial>
        <visual>
            <origin rpy="0 0 0" xyz="-0.005 -0.07 -0.22" />
            <geometry>
                <mesh filename="package://modelo_description/meshes/link_3.stl" scale="0.001 0.001 0.001" />
            </geometry>
            <material name="blue" />
        </visual>
        <collision>
            <origin rpy="0 0 0" xyz="-0.005 -0.07 -0.22" />
            <geometry>
                <mesh filename="package://modelo_description/meshes/link_3.stl" scale="0.001 0.001 0.001" />
            </geometry>
        </collision>
    </link>
    <link name="link_4">
        <inertial>
            <origin rpy="0 0 0" xyz="-0.04671583823132678 -0.006114743040103704 0.01335347313130314" />
            <mass value="0.126071" />
            <inertia ixx="0.000088940685" ixy="0" ixz="0.00000611033" iyy="0.0001763" iyz="0" izz="0.0001979" />
        </inertial>
        <visual>
            <origin rpy="0 0 0" xyz="-0.005 -0.07 -0.42" />
            <geometry>
                <mesh filename="package://modelo_description/meshes/link_4.stl" scale="0.001 0.001 0.001" />
            </geometry>
            <material name="orange" />
        </visual>
        <collision>
            <origin rpy="0 0 0" xyz="-0.005 -0.07 -0.42" />
            <geometry>
                <mesh filename="package://modelo_description/meshes/link_4.stl" scale="0.001 0.001 0.001" />
            </geometry>
        </collision>
    </link>
    <link name="link_5">
        <inertial>
            <origin rpy="0 0 0" xyz="-0.00044650849455328545 -0.05778279171036697 -2.7755575615628914e-16" />
            <mass value="0.488452" />
            <inertia ixx="0.001155" ixy="0" ixz="0" iyy="0.0007053" iyz="0" izz="0.001054" />
        </inertial>
        <visual>
            <origin rpy="0 0 0" xyz="0.075 -0.035 -0.42" />
            <geometry>
                <mesh filename="package://modelo_description/meshes/link_5.stl" scale="0.001 0.001 0.001" />
            </geometry>
            <material name="blue" />
        </visual>
        <collision>
            <origin rpy="0 0 0" xyz="0.075 -0.035 -0.42" />
            <geometry>
                <mesh filename="package://modelo_description/meshes/link_5.stl" scale="0.001 0.001 0.001" />
            </geometry>
        </collision>
    </link>
    <link name="link_6">
        <inertial>
            <origin rpy="0 0 0" xyz="-0.00683271348055893 -8.116383311621012e-06 0.024999999998279177" />
            <mass value="0.0123861" />
            <inertia ixx="0.000039194942" ixy="0" ixz="0" iyy="0.000058851989" iyz="0" izz="0.000056762072" />
        </inertial>
        <visual>
            <origin rpy="0 0 0" xyz="0.07679 0.070058 -0.395" />
            <geometry>
                <mesh filename="package://modelo_description/meshes/link_6.stl" scale="0.001 0.001 0.001" />
            </geometry>
            <material name="orange" />
        </visual>
        <collision>
            <origin rpy="0 0 0" xyz="0.07679 0.070058 -0.395" />
            <geometry>
                <mesh filename="package://modelo_description/meshes/link_6.stl" scale="0.001 0.001 0.001" />
            </geometry>
        </collision>
    </link>
    <link name="link_7">
        <inertial>
            <origin rpy="0 0 0" xyz="-0.008082563695983674 -9.665388285423626e-06 -3.3306690738754696e-16" />
            <mass value="0.001457" />
            <inertia ixx="0.000003254171" ixy="0" ixz="0" iyy="0.000001820288" iyz="0" izz="0.000001820286" />
        </inertial>
        <visual>
            <origin rpy="0 0 0" xyz="0.11679 0.070105 -0.42" />
            <geometry>
                <mesh filename="package://modelo_description/meshes/link_7.stl" scale="0.001 0.001 0.001" />
            </geometry>
            <material name="blue" />
        </visual>
        <collision>
            <origin rpy="0 0 0" xyz="0.11679 0.070105 -0.42" />
            <geometry>
                <mesh filename="package://modelo_description/meshes/link_7.stl" scale="0.001 0.001 0.001" />
            </geometry>
        </collision>
    </link>
    <link name="NEMA17_1">
        <inertial>
            <origin rpy="0 0 0" xyz="-0.017979645478686204 9.8483682348105e-08 -7.507921800931072e-08" />
            <mass value="0.37807" />
            <inertia ixx="0.000088375151" ixy="0" ixz="0" iyy="0.000080538853" iyz="0" izz="0.000080539183" />
        </inertial>
        <visual>
            <origin rpy="0 0 0" xyz="0.005 -0.07 -0.42" />
            <geometry>
                <mesh filename="package://modelo_description/meshes/NEMA17_1.stl" scale="0.001 0.001 0.001" />
            </geometry>
            <material name="orange" />
        </visual>
        <collision>
            <origin rpy="0 0 0" xyz="0.005 -0.07 -0.42" />
            <geometry>
                <mesh filename="package://modelo_description/meshes/NEMA17_1.stl" scale="0.001 0.001 0.001" />
            </geometry>
        </collision>
    </link>
    <link name="NEMA17_2">
        <inertial>
            <origin rpy="0 0 0" xyz="4.619561776164627e-08 0.01797957811301021 -3.299982803683932e-08" />
            <mass value="0.37807" />
            <inertia ixx="0.000088375151" ixy="0" ixz="0" iyy="0.000080538853" iyz="0" izz="0.000080539183" />
        </inertial>
        <visual>
            <origin rpy="0 0 0" xyz="0.075 -0.045 -0.42" />
            <geometry>
                <mesh filename="package://modelo_description/meshes/NEMA17_2.stl" scale="0.001 0.001 0.001" />
            </geometry>
            <material name="blue" />
        </visual>
        <collision>
            <origin rpy="0 0 0" xyz="0.075 -0.045 -0.42" />
            <geometry>
                <mesh filename="package://modelo_description/meshes/NEMA17_2.stl" scale="0.001 0.001 0.001" />
            </geometry>
        </collision>
    </link>
    <link name="NEMA23_1">
        <inertial>
            <origin rpy="0 0 0" xyz="2.216087647950953e-08 -2.5678396917215573e-05 0.03903179757969141" />
            <mass value="1.71147" />
            <inertia ixx="0.00124" ixy="0" ixz="0" iyy="0.001239" iyz="0.000001398796" izz="0.0007837" />
        </inertial>
        <visual>
            <origin rpy="0 0 0" xyz="-0.0 0.008236 -0.17" />
            <geometry>
                <mesh filename="package://modelo_description/meshes/NEMA23_1.stl" scale="0.001 0.001 0.001" />
            </geometry>
            <material name="orange" />
        </visual>
        <collision>
            <origin rpy="0 0 0" xyz="-0.0 0.008236 -0.17" />
            <geometry>
                <mesh filename="package://modelo_description/meshes/NEMA23_1.stl" scale="0.001 0.001 0.001" />
            </geometry>
        </collision>
    </link>
    <link name="NEMA23_2">
        <inertial>
            <origin rpy="0 0 0" xyz="-0.03903179757969144 -2.5678396917222512e-05 2.2160876439469845e-08" />
            <mass value="1.71147" />
            <inertia ixx="0.00124" ixy="0" ixz="0" iyy="0.001239" iyz="0.000001398796" izz="0.0007837" />
        </inertial>
        <visual>
            <origin rpy="0 0 0" xyz="0.005 -0.07 -0.22" />
            <geometry>
                <mesh filename="package://modelo_description/meshes/NEMA23_2.stl" scale="0.001 0.001 0.001" />
            </geometry>
            <material name="blue" />
        </visual>
        <collision>
            <origin rpy="0 0 0" xyz="0.005 -0.07 -0.22" />
            <geometry>
                <mesh filename="package://modelo_description/meshes/NEMA23_2.stl" scale="0.001 0.001 0.001" />
            </geometry>
        </collision>
    </link>
    <link name="garra">
        <inertial>
            <origin rpy="0 0 0" xyz="-0.03590834296259646 -3.6387512495197893e-05 -0.00275221699917072" />
            <mass value="0.0195293" />
            <inertia ixx="0.0001552" ixy="0" ixz="0" iyy="0.0001843" iyz="0" izz="0.0001331" />
        </inertial>
        <visual>
            <origin rpy="0 0 0" xyz="0.13179 0.070123 -0.42" />
            <geometry>
                <mesh filename="package://modelo_description/meshes/garra.stl" scale="0.001 0.001 0.001" />
            </geometry>
            <material name="orange" />
        </visual>
        <collision>
            <origin rpy="0 0 0" xyz="0.13179 0.070123 -0.42" />
            <geometry>
                <mesh filename="package://modelo_description/meshes/garra.stl" scale="0.001 0.001 0.001" />
            </geometry>
        </collision>
    </link>
    <link name="world" />
    <joint name="fixed" type="fixed">
        <parent link="world" />
        <child link="base_link" />
    </joint>
    <joint name="Rigid1" type="fixed">
        <origin rpy="0 0 0" xyz="0.0 0.0 0.05" />
        <parent link="base_link" />
        <child link="link_1" />
    </joint>
    <joint name="rev2" type="continuous">
        <origin rpy="0 0 0" xyz="0.0 0.0 0.107" />
        <parent link="link_1" />
        <child link="link_2" />
        <axis xyz="0 0 -1" />
    </joint>
    <joint name="rev3" type="revolute">
        <origin rpy="0 0 0" xyz="0.005 0.07 0.063" />
        <parent link="link_2" />
        <child link="link_3" />
        <axis xyz="-1 0 0" />
        <limit effort="100" lower="0.0" upper="1.570796" velocity="10" />
    </joint>
    <joint name="rev4" type="revolute">
        <origin rpy="0 0 0" xyz="0.0 0.0 0.2" />
        <parent link="link_3" />
        <child link="link_4" />
        <axis xyz="-1 0 0" />
        <limit effort="100" lower="0.0" upper="3.141593" velocity="10" />
    </joint>
    <joint name="rev5" type="continuous">
        <origin rpy="0 0 0" xyz="-0.08 -0.035 0.0" />
        <parent link="link_4" />
        <child link="link_5" />
        <axis xyz="0 1 0" />
    </joint>
    <joint name="rev6" type="revolute">
        <origin rpy="0 0 0" xyz="-0.00179 -0.105058 -0.025" />
        <parent link="link_5" />
        <child link="link_6" />
        <axis xyz="0 0 -1" />
        <limit effort="100" lower="-3.141593" upper="0.0" velocity="10" />
    </joint>
    <joint name="rev7" type="continuous">
        <origin rpy="0 0 0" xyz="-0.04 -4.7e-05 0.025" />
        <parent link="link_6" />
        <child link="link_7" />
        <axis xyz="1 0 0" />
    </joint>
    <joint name="Rigid8" type="fixed">
        <origin rpy="0 0 0" xyz="-0.01 0.0 0.0" />
        <parent link="link_4" />
        <child link="NEMA17_1" />
    </joint>
    <joint name="Rigid9" type="fixed">
        <origin rpy="0 0 0" xyz="-0.08 -0.025 0.0" />
        <parent link="link_4" />
        <child link="NEMA17_2" />
    </joint>
    <joint name="Rigid10" type="fixed">
        <origin rpy="0 0 0" xyz="0.0 -0.008236 0.013" />
        <parent link="link_2" />
        <child link="NEMA23_1" />
    </joint>
    <joint name="Rigid11" type="fixed">
        <origin rpy="0 0 0" xyz="-0.005 0.07 0.063" />
        <parent link="link_2" />
        <child link="NEMA23_2" />
    </joint>
    <joint name="Rigid12" type="fixed">
        <origin rpy="0 0 0" xyz="-0.015 -1.8e-05 0.0" />
        <parent link="link_7" />
        <child link="garra" />
    </joint>
    <gazebo>
        <plugin filename="libgazebo_ros_control.so" name="gazebo_ros_control">
            <robotNamespace>/modelo</robotNamespace>
        </plugin>
    </gazebo>
    <transmission name="trans_rev2">
        <type>transmission_interface/SimpleTransmission</type>
        <joint name="rev2">
            <hardwareInterface>hardware_interface/EffortJointInterface</hardwareInterface>
        </joint>
        <actuator name="rev2_motor">
            <hardwareInterface>hardware_interface/EffortJointInterface</hardwareInterface>
            <mechanicalReduction>1</mechanicalReduction>
        </actuator>
    </transmission>
    <transmission name="trans_rev3">
        <type>transmission_interface/SimpleTransmission</type>
        <joint name="rev3">
            <hardwareInterface>hardware_interface/EffortJointInterface</hardwareInterface>
        </joint>
        <actuator name="rev3_motor">
            <hardwareInterface>hardware_interface/EffortJointInterface</hardwareInterface>
            <mechanicalReduction>1</mechanicalReduction>
        </actuator>
    </transmission>
    <transmission name="trans_rev4">
        <type>transmission_interface/SimpleTransmission</type>
        <joint name="rev4">
            <hardwareInterface>hardware_interface/EffortJointInterface</hardwareInterface>
        </joint>
        <actuator name="rev4_motor">
            <hardwareInterface>hardware_interface/EffortJointInterface</hardwareInterface>
            <mechanicalReduction>1</mechanicalReduction>
        </actuator>
    </transmission>
    <transmission name="trans_rev5">
        <type>transmission_interface/SimpleTransmission</type>
        <joint name="rev5">
            <hardwareInterface>hardware_interface/EffortJointInterface</hardwareInterface>
        </joint>
        <actuator name="rev5_motor">
            <hardwareInterface>hardware_interface/EffortJointInterface</hardwareInterface>
            <mechanicalReduction>1</mechanicalReduction>
        </actuator>
    </transmission>
    <transmission name="trans_rev6">
        <type>transmission_interface/SimpleTransmission</type>
        <joint name="rev6">
            <hardwareInterface>hardware_interface/EffortJointInterface</hardwareInterface>
        </joint>
        <actuator name="rev6_motor">
            <hardwareInterface>hardware_interface/EffortJointInterface</hardwareInterface>
            <mechanicalReduction>1</mechanicalReduction>
        </actuator>
    </transmission>
    <transmission name="trans_rev7">
        <type>transmission_interface/SimpleTransmission</type>
        <joint name="rev7">
            <hardwareInterface>hardware_interface/EffortJointInterface</hardwareInterface>
        </joint>
        <actuator name="rev7_motor">
            <hardwareInterface>hardware_interface/EffortJointInterface</hardwareInterface>
            <mechanicalReduction>1</mechanicalReduction>
        </actuator>
    </transmission>
    <gazebo>
        <plugin name="gazebo_ros_control" filename="libgazebo_ros_control.so">
            <robotNamespace>/</robotNamespace>
        </plugin>
    </gazebo>
</robot>